/var/spool/slurmd/job4413672/slurm_script: line 13: conda: command not found
r22
Thu Jun 27 00:56:46 PDT 2024
Date and time: 2024-06-27 00:56:47.841216
len_slice  n_select_slc  beams  n_optimization_restarts  output_file
3 2 1 10 best_slices_test.txt
Redshifts:  [0.  0.2 0.5 1.  2.  3. ]
Computing loss function for slice 0
 /rhome/yyang440/bigdata/anaconda3/envs/gpy-env/lib/python3.8/site-packages/GPy/kern/src/stationary.py:137: RuntimeWarning:overflow encountered in square
 /rhome/yyang440/bigdata/anaconda3/envs/gpy-env/lib/python3.8/site-packages/GPy/kern/src/stationary.py:138: RuntimeWarning:invalid value encountered in add
 /rhome/yyang440/bigdata/anaconda3/envs/gpy-env/lib/python3.8/site-packages/GPy/kern/src/stationary.py:137: RuntimeWarning:overflow encountered in square
 /rhome/yyang440/bigdata/anaconda3/envs/gpy-env/lib/python3.8/site-packages/GPy/kern/src/stationary.py:138: RuntimeWarning:invalid value encountered in add
Time now: 2024-06-27 00:56:52.294418
Loss function for slice 0 = 0.05918973374770887
Computing loss function for slice 1
 /rhome/yyang440/bigdata/anaconda3/envs/gpy-env/lib/python3.8/site-packages/GPy/kern/src/stationary.py:243: RuntimeWarning:invalid value encountered in true_divide
Time now: 2024-06-27 00:56:57.559613
Loss function for slice 1 = 0.04855472447860993
Computing loss function for slice 2
 /rhome/yyang440/bigdata/anaconda3/envs/gpy-env/lib/python3.8/site-packages/GPy/kern/src/stationary.py:243: RuntimeWarning:invalid value encountered in true_divide
Time now: 2024-06-27 00:57:02.753341
Loss function for slice 2 = 0.07850701692812018
Computing loss function for slice 3
 /rhome/yyang440/bigdata/anaconda3/envs/gpy-env/lib/python3.8/site-packages/GPy/kern/src/stationary.py:137: RuntimeWarning:overflow encountered in square
 /rhome/yyang440/bigdata/anaconda3/envs/gpy-env/lib/python3.8/site-packages/GPy/kern/src/stationary.py:138: RuntimeWarning:invalid value encountered in add
 /rhome/yyang440/bigdata/anaconda3/envs/gpy-env/lib/python3.8/site-packages/GPy/kern/src/stationary.py:137: RuntimeWarning:overflow encountered in square
 /rhome/yyang440/bigdata/anaconda3/envs/gpy-env/lib/python3.8/site-packages/GPy/kern/src/stationary.py:138: RuntimeWarning:invalid value encountered in add
 /rhome/yyang440/bigdata/anaconda3/envs/gpy-env/lib/python3.8/site-packages/GPy/kern/src/stationary.py:137: RuntimeWarning:overflow encountered in square
 /rhome/yyang440/bigdata/anaconda3/envs/gpy-env/lib/python3.8/site-packages/GPy/kern/src/stationary.py:138: RuntimeWarning:invalid value encountered in add
Time now: 2024-06-27 00:57:06.502085
Loss function for slice 3 = 0.04992153706710487
Computing loss function for slice 4
 /rhome/yyang440/bigdata/anaconda3/envs/gpy-env/lib/python3.8/site-packages/GPy/kern/src/stationary.py:137: RuntimeWarning:overflow encountered in square
 /rhome/yyang440/bigdata/anaconda3/envs/gpy-env/lib/python3.8/site-packages/GPy/kern/src/stationary.py:138: RuntimeWarning:invalid value encountered in add
 /rhome/yyang440/bigdata/anaconda3/envs/gpy-env/lib/python3.8/site-packages/GPy/kern/src/stationary.py:137: RuntimeWarning:overflow encountered in square
 /rhome/yyang440/bigdata/anaconda3/envs/gpy-env/lib/python3.8/site-packages/GPy/kern/src/stationary.py:138: RuntimeWarning:invalid value encountered in add
 /rhome/yyang440/bigdata/anaconda3/envs/gpy-env/lib/python3.8/site-packages/GPy/kern/src/stationary.py:137: RuntimeWarning:overflow encountered in square
 /rhome/yyang440/bigdata/anaconda3/envs/gpy-env/lib/python3.8/site-packages/GPy/kern/src/stationary.py:138: RuntimeWarning:invalid value encountered in add
 /rhome/yyang440/bigdata/anaconda3/envs/gpy-env/lib/python3.8/site-packages/GPy/kern/src/stationary.py:137: RuntimeWarning:overflow encountered in square
 /rhome/yyang440/bigdata/anaconda3/envs/gpy-env/lib/python3.8/site-packages/GPy/kern/src/stationary.py:138: RuntimeWarning:invalid value encountered in add
Time now: 2024-06-27 00:57:11.151704
Loss function for slice 4 = 0.04907647775090673
Computing loss function for slice 5
 /rhome/yyang440/bigdata/anaconda3/envs/gpy-env/lib/python3.8/site-packages/GPy/kern/src/stationary.py:137: RuntimeWarning:overflow encountered in square
 /rhome/yyang440/bigdata/anaconda3/envs/gpy-env/lib/python3.8/site-packages/GPy/kern/src/stationary.py:138: RuntimeWarning:invalid value encountered in add
 /rhome/yyang440/bigdata/anaconda3/envs/gpy-env/lib/python3.8/site-packages/GPy/kern/src/stationary.py:137: RuntimeWarning:overflow encountered in square
 /rhome/yyang440/bigdata/anaconda3/envs/gpy-env/lib/python3.8/site-packages/GPy/kern/src/stationary.py:138: RuntimeWarning:invalid value encountered in add
Time now: 2024-06-27 00:57:19.098357
Loss function for slice 5 = 0.056673733578489545
Computing loss function for slice 6
 /rhome/yyang440/bigdata/anaconda3/envs/gpy-env/lib/python3.8/site-packages/GPy/kern/src/stationary.py:137: RuntimeWarning:overflow encountered in square
 /rhome/yyang440/bigdata/anaconda3/envs/gpy-env/lib/python3.8/site-packages/GPy/kern/src/stationary.py:138: RuntimeWarning:invalid value encountered in add
 /rhome/yyang440/bigdata/anaconda3/envs/gpy-env/lib/python3.8/site-packages/GPy/kern/src/stationary.py:137: RuntimeWarning:overflow encountered in square
 /rhome/yyang440/bigdata/anaconda3/envs/gpy-env/lib/python3.8/site-packages/GPy/kern/src/stationary.py:138: RuntimeWarning:invalid value encountered in add
 /rhome/yyang440/bigdata/anaconda3/envs/gpy-env/lib/python3.8/site-packages/GPy/kern/src/stationary.py:137: RuntimeWarning:overflow encountered in square
 /rhome/yyang440/bigdata/anaconda3/envs/gpy-env/lib/python3.8/site-packages/GPy/kern/src/stationary.py:138: RuntimeWarning:invalid value encountered in add
Time now: 2024-06-27 00:57:23.031899
Loss function for slice 6 = 0.03855550487552206
Computing loss function for slice 7
Time now: 2024-06-27 00:57:26.479009
Loss function for slice 7 = 0.10222340221672736
Computing loss function for slice 8
 /rhome/yyang440/bigdata/anaconda3/envs/gpy-env/lib/python3.8/site-packages/GPy/kern/src/stationary.py:137: RuntimeWarning:overflow encountered in square
 /rhome/yyang440/bigdata/anaconda3/envs/gpy-env/lib/python3.8/site-packages/GPy/kern/src/stationary.py:138: RuntimeWarning:invalid value encountered in add
 /rhome/yyang440/bigdata/anaconda3/envs/gpy-env/lib/python3.8/site-packages/GPy/kern/src/stationary.py:137: RuntimeWarning:overflow encountered in square
 /rhome/yyang440/bigdata/anaconda3/envs/gpy-env/lib/python3.8/site-packages/GPy/kern/src/stationary.py:138: RuntimeWarning:invalid value encountered in add
Time now: 2024-06-27 00:57:31.514611
Loss function for slice 8 = 0.09074877847179287
Computing loss function for slice 9
 /rhome/yyang440/bigdata/anaconda3/envs/gpy-env/lib/python3.8/site-packages/GPy/kern/src/stationary.py:137: RuntimeWarning:overflow encountered in square
 /rhome/yyang440/bigdata/anaconda3/envs/gpy-env/lib/python3.8/site-packages/GPy/kern/src/stationary.py:138: RuntimeWarning:invalid value encountered in add
 /rhome/yyang440/bigdata/anaconda3/envs/gpy-env/lib/python3.8/site-packages/GPy/kern/src/stationary.py:137: RuntimeWarning:overflow encountered in square
 /rhome/yyang440/bigdata/anaconda3/envs/gpy-env/lib/python3.8/site-packages/GPy/kern/src/stationary.py:138: RuntimeWarning:invalid value encountered in add
Time now: 2024-06-27 00:57:35.149265
Loss function for slice 9 = 0.058594786310453346
Computing loss function for slice 10
 /rhome/yyang440/bigdata/anaconda3/envs/gpy-env/lib/python3.8/site-packages/GPy/kern/src/stationary.py:137: RuntimeWarning:overflow encountered in square
 /rhome/yyang440/bigdata/anaconda3/envs/gpy-env/lib/python3.8/site-packages/GPy/kern/src/stationary.py:138: RuntimeWarning:invalid value encountered in add
 /rhome/yyang440/bigdata/anaconda3/envs/gpy-env/lib/python3.8/site-packages/GPy/kern/src/stationary.py:137: RuntimeWarning:overflow encountered in square
 /rhome/yyang440/bigdata/anaconda3/envs/gpy-env/lib/python3.8/site-packages/GPy/kern/src/stationary.py:138: RuntimeWarning:invalid value encountered in add
Time now: 2024-06-27 00:57:40.012171
Loss function for slice 10 = 0.05758548489061216
Computing loss function for slice 11
 /rhome/yyang440/bigdata/anaconda3/envs/gpy-env/lib/python3.8/site-packages/GPy/kern/src/stationary.py:137: RuntimeWarning:overflow encountered in square
 /rhome/yyang440/bigdata/anaconda3/envs/gpy-env/lib/python3.8/site-packages/GPy/kern/src/stationary.py:138: RuntimeWarning:invalid value encountered in add
 /rhome/yyang440/bigdata/anaconda3/envs/gpy-env/lib/python3.8/site-packages/GPy/kern/src/stationary.py:137: RuntimeWarning:overflow encountered in square
 /rhome/yyang440/bigdata/anaconda3/envs/gpy-env/lib/python3.8/site-packages/GPy/kern/src/stationary.py:138: RuntimeWarning:invalid value encountered in add
 /rhome/yyang440/bigdata/anaconda3/envs/gpy-env/lib/python3.8/site-packages/GPy/kern/src/stationary.py:243: RuntimeWarning:invalid value encountered in true_divide
Time now: 2024-06-27 00:57:47.677854
Loss function for slice 11 = 0.10778075785877768
Computing loss function for slice 12
 /rhome/yyang440/bigdata/anaconda3/envs/gpy-env/lib/python3.8/site-packages/GPy/kern/src/stationary.py:137: RuntimeWarning:overflow encountered in square
 /rhome/yyang440/bigdata/anaconda3/envs/gpy-env/lib/python3.8/site-packages/GPy/kern/src/stationary.py:138: RuntimeWarning:invalid value encountered in add
 /rhome/yyang440/bigdata/anaconda3/envs/gpy-env/lib/python3.8/site-packages/GPy/kern/src/stationary.py:137: RuntimeWarning:overflow encountered in square
 /rhome/yyang440/bigdata/anaconda3/envs/gpy-env/lib/python3.8/site-packages/GPy/kern/src/stationary.py:138: RuntimeWarning:invalid value encountered in add
 /rhome/yyang440/bigdata/anaconda3/envs/gpy-env/lib/python3.8/site-packages/GPy/kern/src/stationary.py:137: RuntimeWarning:overflow encountered in square
 /rhome/yyang440/bigdata/anaconda3/envs/gpy-env/lib/python3.8/site-packages/GPy/kern/src/stationary.py:138: RuntimeWarning:invalid value encountered in add
Time now: 2024-06-27 00:57:52.523218
Loss function for slice 12 = 0.04431475211170771
Computing loss function for slice 13
 /rhome/yyang440/bigdata/anaconda3/envs/gpy-env/lib/python3.8/site-packages/GPy/kern/src/stationary.py:137: RuntimeWarning:overflow encountered in square
 /rhome/yyang440/bigdata/anaconda3/envs/gpy-env/lib/python3.8/site-packages/GPy/kern/src/stationary.py:138: RuntimeWarning:invalid value encountered in add
 /rhome/yyang440/bigdata/anaconda3/envs/gpy-env/lib/python3.8/site-packages/GPy/kern/src/stationary.py:137: RuntimeWarning:overflow encountered in square
 /rhome/yyang440/bigdata/anaconda3/envs/gpy-env/lib/python3.8/site-packages/GPy/kern/src/stationary.py:138: RuntimeWarning:invalid value encountered in add
 /rhome/yyang440/bigdata/anaconda3/envs/gpy-env/lib/python3.8/site-packages/GPy/kern/src/stationary.py:137: RuntimeWarning:overflow encountered in square
 /rhome/yyang440/bigdata/anaconda3/envs/gpy-env/lib/python3.8/site-packages/GPy/kern/src/stationary.py:138: RuntimeWarning:invalid value encountered in add
Time now: 2024-06-27 00:58:04.822344
Loss function for slice 13 = 0.08666883223771908
Computing loss function for slice 14
 /rhome/yyang440/bigdata/anaconda3/envs/gpy-env/lib/python3.8/site-packages/GPy/kern/src/stationary.py:137: RuntimeWarning:overflow encountered in square
 /rhome/yyang440/bigdata/anaconda3/envs/gpy-env/lib/python3.8/site-packages/GPy/kern/src/stationary.py:138: RuntimeWarning:invalid value encountered in add
 /rhome/yyang440/bigdata/anaconda3/envs/gpy-env/lib/python3.8/site-packages/GPy/kern/src/stationary.py:137: RuntimeWarning:overflow encountered in square
 /rhome/yyang440/bigdata/anaconda3/envs/gpy-env/lib/python3.8/site-packages/GPy/kern/src/stationary.py:138: RuntimeWarning:invalid value encountered in add
 /rhome/yyang440/bigdata/anaconda3/envs/gpy-env/lib/python3.8/site-packages/GPy/kern/src/stationary.py:243: RuntimeWarning:invalid value encountered in true_divide
 /rhome/yyang440/bigdata/anaconda3/envs/gpy-env/lib/python3.8/site-packages/GPy/kern/src/stationary.py:243: RuntimeWarning:invalid value encountered in true_divide
Time now: 2024-06-27 00:58:16.130819
Loss function for slice 14 = 0.04394509161307605
Computing loss function for slice 15
 /rhome/yyang440/bigdata/anaconda3/envs/gpy-env/lib/python3.8/site-packages/GPy/kern/src/stationary.py:137: RuntimeWarning:overflow encountered in square
 /rhome/yyang440/bigdata/anaconda3/envs/gpy-env/lib/python3.8/site-packages/GPy/kern/src/stationary.py:138: RuntimeWarning:invalid value encountered in add
 /rhome/yyang440/bigdata/anaconda3/envs/gpy-env/lib/python3.8/site-packages/GPy/kern/src/stationary.py:137: RuntimeWarning:overflow encountered in square
 /rhome/yyang440/bigdata/anaconda3/envs/gpy-env/lib/python3.8/site-packages/GPy/kern/src/stationary.py:138: RuntimeWarning:invalid value encountered in add
Time now: 2024-06-27 00:58:23.309501
Loss function for slice 15 = 0.03707402726266724
Computing loss function for slice 16
 /rhome/yyang440/bigdata/anaconda3/envs/gpy-env/lib/python3.8/site-packages/GPy/kern/src/stationary.py:137: RuntimeWarning:overflow encountered in square
 /rhome/yyang440/bigdata/anaconda3/envs/gpy-env/lib/python3.8/site-packages/GPy/kern/src/stationary.py:138: RuntimeWarning:invalid value encountered in add
 /rhome/yyang440/bigdata/anaconda3/envs/gpy-env/lib/python3.8/site-packages/GPy/kern/src/stationary.py:137: RuntimeWarning:overflow encountered in square
 /rhome/yyang440/bigdata/anaconda3/envs/gpy-env/lib/python3.8/site-packages/GPy/kern/src/stationary.py:138: RuntimeWarning:invalid value encountered in add
 /rhome/yyang440/bigdata/anaconda3/envs/gpy-env/lib/python3.8/site-packages/GPy/kern/src/stationary.py:137: RuntimeWarning:overflow encountered in square
 /rhome/yyang440/bigdata/anaconda3/envs/gpy-env/lib/python3.8/site-packages/GPy/kern/src/stationary.py:138: RuntimeWarning:invalid value encountered in add
 /rhome/yyang440/bigdata/anaconda3/envs/gpy-env/lib/python3.8/site-packages/GPy/kern/src/stationary.py:137: RuntimeWarning:overflow encountered in square
 /rhome/yyang440/bigdata/anaconda3/envs/gpy-env/lib/python3.8/site-packages/GPy/kern/src/stationary.py:138: RuntimeWarning:invalid value encountered in add
Time now: 2024-06-27 00:58:27.654174
Loss function for slice 16 = 0.06707872552253724
Computing loss function for slice 17
 /rhome/yyang440/bigdata/anaconda3/envs/gpy-env/lib/python3.8/site-packages/GPy/kern/src/stationary.py:243: RuntimeWarning:invalid value encountered in true_divide
 /rhome/yyang440/bigdata/anaconda3/envs/gpy-env/lib/python3.8/site-packages/GPy/kern/src/stationary.py:137: RuntimeWarning:overflow encountered in square
 /rhome/yyang440/bigdata/anaconda3/envs/gpy-env/lib/python3.8/site-packages/GPy/kern/src/stationary.py:138: RuntimeWarning:invalid value encountered in add
 /rhome/yyang440/bigdata/anaconda3/envs/gpy-env/lib/python3.8/site-packages/GPy/kern/src/stationary.py:243: RuntimeWarning:invalid value encountered in true_divide
 /rhome/yyang440/bigdata/anaconda3/envs/gpy-env/lib/python3.8/site-packages/GPy/kern/src/stationary.py:137: RuntimeWarning:overflow encountered in square
 /rhome/yyang440/bigdata/anaconda3/envs/gpy-env/lib/python3.8/site-packages/GPy/kern/src/stationary.py:138: RuntimeWarning:invalid value encountered in add
 /rhome/yyang440/bigdata/anaconda3/envs/gpy-env/lib/python3.8/site-packages/GPy/kern/src/stationary.py:137: RuntimeWarning:overflow encountered in square
 /rhome/yyang440/bigdata/anaconda3/envs/gpy-env/lib/python3.8/site-packages/GPy/kern/src/stationary.py:138: RuntimeWarning:invalid value encountered in add
 /rhome/yyang440/bigdata/anaconda3/envs/gpy-env/lib/python3.8/site-packages/GPy/kern/src/stationary.py:243: RuntimeWarning:invalid value encountered in true_divide
Time now: 2024-06-27 00:58:33.394067
Loss function for slice 17 = 0.04837859638580765
Computing loss function for slice 18
 /rhome/yyang440/bigdata/anaconda3/envs/gpy-env/lib/python3.8/site-packages/GPy/kern/src/stationary.py:243: RuntimeWarning:invalid value encountered in true_divide
 /rhome/yyang440/bigdata/anaconda3/envs/gpy-env/lib/python3.8/site-packages/GPy/kern/src/stationary.py:137: RuntimeWarning:overflow encountered in square
 /rhome/yyang440/bigdata/anaconda3/envs/gpy-env/lib/python3.8/site-packages/GPy/kern/src/stationary.py:138: RuntimeWarning:invalid value encountered in add
 /rhome/yyang440/bigdata/anaconda3/envs/gpy-env/lib/python3.8/site-packages/GPy/kern/src/stationary.py:137: RuntimeWarning:overflow encountered in square
 /rhome/yyang440/bigdata/anaconda3/envs/gpy-env/lib/python3.8/site-packages/GPy/kern/src/stationary.py:138: RuntimeWarning:invalid value encountered in add
Time now: 2024-06-27 00:58:38.090771
Loss function for slice 18 = 0.04896197845845726
Computing loss function for slice 19
 /rhome/yyang440/bigdata/anaconda3/envs/gpy-env/lib/python3.8/site-packages/GPy/kern/src/stationary.py:137: RuntimeWarning:overflow encountered in square
 /rhome/yyang440/bigdata/anaconda3/envs/gpy-env/lib/python3.8/site-packages/GPy/kern/src/stationary.py:138: RuntimeWarning:invalid value encountered in add
 /rhome/yyang440/bigdata/anaconda3/envs/gpy-env/lib/python3.8/site-packages/GPy/kern/src/stationary.py:137: RuntimeWarning:overflow encountered in square
 /rhome/yyang440/bigdata/anaconda3/envs/gpy-env/lib/python3.8/site-packages/GPy/kern/src/stationary.py:138: RuntimeWarning:invalid value encountered in add
Time now: 2024-06-27 00:58:45.244792
Loss function for slice 19 = 0.13009069285497862
Computing loss function for slice 20
 /rhome/yyang440/bigdata/anaconda3/envs/gpy-env/lib/python3.8/site-packages/GPy/kern/src/stationary.py:243: RuntimeWarning:invalid value encountered in true_divide
 /rhome/yyang440/bigdata/anaconda3/envs/gpy-env/lib/python3.8/site-packages/GPy/kern/src/stationary.py:137: RuntimeWarning:overflow encountered in square
 /rhome/yyang440/bigdata/anaconda3/envs/gpy-env/lib/python3.8/site-packages/GPy/kern/src/stationary.py:138: RuntimeWarning:invalid value encountered in add
 /rhome/yyang440/bigdata/anaconda3/envs/gpy-env/lib/python3.8/site-packages/GPy/kern/src/stationary.py:137: RuntimeWarning:overflow encountered in square
 /rhome/yyang440/bigdata/anaconda3/envs/gpy-env/lib/python3.8/site-packages/GPy/kern/src/stationary.py:138: RuntimeWarning:invalid value encountered in add
 /rhome/yyang440/bigdata/anaconda3/envs/gpy-env/lib/python3.8/site-packages/GPy/kern/src/stationary.py:137: RuntimeWarning:overflow encountered in square
 /rhome/yyang440/bigdata/anaconda3/envs/gpy-env/lib/python3.8/site-packages/GPy/kern/src/stationary.py:138: RuntimeWarning:invalid value encountered in add
 /rhome/yyang440/bigdata/anaconda3/envs/gpy-env/lib/python3.8/site-packages/GPy/kern/src/stationary.py:137: RuntimeWarning:overflow encountered in square
 /rhome/yyang440/bigdata/anaconda3/envs/gpy-env/lib/python3.8/site-packages/GPy/kern/src/stationary.py:138: RuntimeWarning:invalid value encountered in add
Time now: 2024-06-27 00:58:50.431009
Loss function for slice 20 = 0.0626820497348419
Computing loss function for slice 21
 /rhome/yyang440/bigdata/anaconda3/envs/gpy-env/lib/python3.8/site-packages/GPy/kern/src/stationary.py:137: RuntimeWarning:overflow encountered in square
 /rhome/yyang440/bigdata/anaconda3/envs/gpy-env/lib/python3.8/site-packages/GPy/kern/src/stationary.py:138: RuntimeWarning:invalid value encountered in add
 /rhome/yyang440/bigdata/anaconda3/envs/gpy-env/lib/python3.8/site-packages/GPy/kern/src/stationary.py:137: RuntimeWarning:overflow encountered in square
 /rhome/yyang440/bigdata/anaconda3/envs/gpy-env/lib/python3.8/site-packages/GPy/kern/src/stationary.py:138: RuntimeWarning:invalid value encountered in add
Time now: 2024-06-27 00:58:55.503718
Loss function for slice 21 = 0.15667731277423202
Computing loss function for slice 22
Time now: 2024-06-27 00:59:00.793302
Loss function for slice 22 = 0.07308062431634503
Computing loss function for slice 23
 /rhome/yyang440/bigdata/anaconda3/envs/gpy-env/lib/python3.8/site-packages/GPy/kern/src/stationary.py:137: RuntimeWarning:overflow encountered in square
 /rhome/yyang440/bigdata/anaconda3/envs/gpy-env/lib/python3.8/site-packages/GPy/kern/src/stationary.py:138: RuntimeWarning:invalid value encountered in add
Time now: 2024-06-27 00:59:06.147846
Loss function for slice 23 = 0.06693585175584342
Computing loss function for slice 24
 /rhome/yyang440/bigdata/anaconda3/envs/gpy-env/lib/python3.8/site-packages/GPy/kern/src/stationary.py:137: RuntimeWarning:overflow encountered in square
 /rhome/yyang440/bigdata/anaconda3/envs/gpy-env/lib/python3.8/site-packages/GPy/kern/src/stationary.py:138: RuntimeWarning:invalid value encountered in add
